<?xml version="1.0"?>
<robot name="hybrid_robot">

  <!-- ================= BASE LINK ================= -->
  <link name="base_link">
    <inertial>
      <origin xyz="0 0 0"/>
      <mass value="1.0"/>
      <inertia ixx="0.01" iyy="0.01" izz="0.01"
               ixy="0" ixz="0" iyz="0"/>
    </inertial>

    <visual>
      <geometry>
        <box size="0.1 0.1 0.1"/>
      </geometry>
    </visual>

    <collision>
      <geometry>
        <box size="0.1 0.1 0.1"/>
      </geometry>
    </collision>
  </link>

  <!-- ================= BASE JOINT ================= -->
  <joint name="base_joint" type="revolute">
    <parent link="base_link"/>
    <child link="link1"/>
    <origin xyz="0 0 0"/>
    <axis xyz="0 0 1"/>
    <limit lower="-3.14" upper="3.14" effort="50" velocity="50"/>
  </joint>

  <!-- ================= LINK 1 ================= -->
  <link name="link1">
    <inertial>
      <origin xyz="0 0 0"/>
      <mass value="1.0"/>
      <inertia ixx="0.005" iyy="0.005" izz="0.005"
               ixy="0" ixz="0" iyz="0"/>
    </inertial>

    <visual>
      <origin xyz="0.1 0 0" rpy="0 1.5708 0"/>
      <geometry>
        <cylinder radius="0.03" length="0.2"/>
      </geometry>
    </visual>

    <collision>
      <origin xyz="0.1 0 0" rpy="0 1.5708 0"/>
      <geometry>
        <cylinder radius="0.03" length="0.2"/>
      </geometry>
    </collision>
  </link>

  <!-- ================= JOINT 1 ================= -->
  <joint name="joint1" type="revolute">
    <parent link="link1"/>
    <child link="link2"/>
    <origin xyz="0.2 0 0"/>
    <axis xyz="0 0 1"/>
    <limit lower="-3.14" upper="3.14" effort="50" velocity="50"/>
  </joint>

  <!-- ================= LINK 2 ================= -->
  <link name="link2">
    <inertial>
      <origin xyz="0 0 0"/>
      <mass value="1.0"/>
      <inertia ixx="0.005" iyy="0.005" izz="0.005"
               ixy="0" ixz="0" iyz="0"/>
    </inertial>

    <visual>
      <origin xyz="0.1 0 0" rpy="0 1.5708 0"/>
      <geometry>
        <cylinder radius="0.03" length="0.2"/>
      </geometry>
    </visual>

    <collision>
      <origin xyz="0.1 0 0" rpy="0 1.5708 0"/>
      <geometry>
        <cylinder radius="0.03" length="0.2"/>
      </geometry>
    </collision>
  </link>

  <!-- ================= JOINT 3 ================= -->
  <joint name="joint3" type="revolute">
    <parent link="base_link"/>
    <child link="link3"/>
    <origin xyz="0 0 0"/>
    <axis xyz="0 0 1"/>
    <limit lower="-3.14" upper="3.14" effort="50" velocity="50"/>
  </joint>

  <!-- ================= LINK 3 ================= -->
  <link name="link3">
    <inertial>
      <origin xyz="0 0 0"/>
      <mass value="1.0"/>
      <inertia ixx="0.005" iyy="0.005" izz="0.005"
               ixy="0" ixz="0" iyz="0"/>
    </inertial>

    <visual>
      <origin xyz="-0.1 0 0" rpy="0 -1.5708 0"/>
      <geometry>
        <cylinder radius="0.03" length="0.2"/>
      </geometry>
    </visual>

    <collision>
      <origin xyz="-0.1 0 0" rpy="0 -1.5708 0"/>
      <geometry>
        <cylinder radius="0.03" length="0.2"/>
      </geometry>
    </collision>
  </link>

  <!-- ================= JOINT 4 ================= -->
  <joint name="joint4" type="revolute">
    <parent link="link3"/>
    <child link="link4"/>
    <origin xyz="-0.2 0 0"/>
    <axis xyz="0 0 1"/>
    <limit lower="-3.14" upper="3.14" effort="50" velocity="50"/>
  </joint>

  <!-- ================= LINK 4 ================= -->
  <link name="link4">
    <inertial>
      <origin xyz="0 0 0"/>
      <mass value="1.0"/>
      <inertia ixx="0.005" iyy="0.005" izz="0.005"
               ixy="0" ixz="0" iyz="0"/>
    </inertial>

    <visual>
      <origin xyz="-0.1 0 0" rpy="0 -1.5708 0"/>
      <geometry>
        <cylinder radius="0.03" length="0.2"/>
      </geometry>
    </visual>

    <collision>
      <origin xyz="-0.1 0 0" rpy="0 -1.5708 0"/>
      <geometry>
        <cylinder radius="0.03" length="0.2"/>
      </geometry>
    </collision>
  </link>

  <!-- ================= ACTUATORS ================= -->
  <ros2_control name="HybridSystem" type="system">
    <hardware>
      <plugin>gazebo_ros2_control/GazeboSystem</plugin>
    </hardware>

    <joint name="base_joint">
      <command_interface name="effort"/>
      <state_interface name="position"/>
      <state_interface name="velocity"/>
      <state_interface name="effort"/>
    </joint>

    <joint name="joint1">
      <command_interface name="velocity"/>
      <state_interface name="position"/>
      <state_interface name="velocity"/>
    </joint>

    <joint name="joint2">
      <command_interface name="velocity"/>
      <state_interface name="position"/>
      <state_interface name="velocity"/>
    </joint>

    <joint name="joint3">
      <command_interface name="velocity"/>
      <state_interface name="position"/>
      <state_interface name="velocity"/>
    </joint>

    <joint name="joint4">
      <command_interface name="velocity"/>
      <state_interface name="position"/>
      <state_interface name="velocity"/>
    </joint>
  </ros2_control>

</robot>

