<mujoco model="hybrid_robot">
    <compiler angle="radian"/>
    <option gravity="0 0 0"/>

    <worldbody>
        <body name="base_link" pos="0 0 0">
            <inertial pos="0 0 0" mass="1.0" diaginertia="0.01 0.01 0.01"/>
            <geom name="base_geom" type="box" size="0.05 0.05 0.05" rgba="0.6 0.6 0.6 1"/>
            <joint name="base_joint" type="hinge" axis="0 0 1" range="-3.14 3.14" limited="true"/>

            <body name="link1" pos="0 0 0">
                <inertial pos="0 0 0" mass="1.0" diaginertia="0.005 0.005 0.005"/>
                <joint name="joint1" type="hinge" axis="0 0 1" range="-3.14 3.14" limited="true"/>
                <geom name="link1_geom" type="cylinder" size="0.03 0.1" pos="0.1 0 0" zaxis="1 0 0" rgba="0.2 0.4 0.9 1"/>

                <body name="link2" pos="0.2 0 0">
                    <inertial pos="0 0 0" mass="1.0" diaginertia="0.005 0.005 0.005"/>
                    <joint name="joint2" type="hinge" axis="0 0 1" range="-3.14 3.14" limited="true"/>
                    <geom name="link2_geom" type="cylinder" size="0.03 0.1" pos="0.1 0 0" zaxis="1 0 0" rgba="0.2 0.9 0.4 1"/>
                </body>
            </body>

            <body name="link3" pos="0 0 0">
                <inertial pos="0 0 0" mass="1.0" diaginertia="0.005 0.005 0.005"/>
                <joint name="joint3" type="hinge" axis="0 0 1" range="-3.14 3.14" limited="true"/>
                <geom name="link3_geom" type="cylinder" size="0.03 0.1" pos="-0.1 0 0" zaxis="-1 0 0" rgba="0.9 0.2 0.2 1"/>

                <body name="link4" pos="-0.2 0 0">
                    <inertial pos="0 0 0" mass="1.0" diaginertia="0.005 0.005 0.005"/>
                    <joint name="joint4" type="hinge" axis="0 0 1" range="-3.14 3.14" limited="true"/>
                    <geom name="link4_geom" type="cylinder" size="0.03 0.1" pos="-0.1 0 0" zaxis="-1 0 0" rgba="0.9 0.9 0.3 1"/>
                </body>
            </body>
        </body>
    </worldbody>

    <actuator>
    <motor name="motor0" joint="base_joint"/>
    <velocity name="vel1" joint="joint1" kv="0.1" ctrllimited="true" ctrlrange="-5 5"/>
    <velocity name="vel2" joint="joint2" kv="0.1" ctrllimited="true" ctrlrange="-5 5"/>
    <velocity name="vel3" joint="joint3" kv="0.1" ctrllimited="true" ctrlrange="-5 5"/>
    <velocity name="vel4" joint="joint4" kv="0.1" ctrllimited="true" ctrlrange="-5 5"/>
    
</actuator>

</mujoco>





